<?xml version="1.0" encoding="utf-8"?>
<!-- This URDF was automatically created by SolidWorks to URDF Exporter! Originally created by Stephen Brawner (brawner@gmail.com) 
     Commit Version: 1.6.0-4-g7f85cfe  Build Version: 1.6.7995.38578
     For more information, please see http://wiki.ros.org/sw_urdf_exporter -->
<robot
  name="urdfAssm2">
  <link
    name="base_link">
    <inertial>
      <origin
        xyz="-0.016740350844899 0.0307423784997515 -0.0323146494975246"
        rpy="0 0 0" />
      <mass
        value="1.83813014538573" />
      <inertia
        ixx="0.0126527136163981"
        ixy="-2.08028592840101E-05"
        ixz="1.89181976316372E-08"
        iyy="0.0214525871748862"
        iyz="-0.000346791397246124"
        izz="0.0108801705210895" />
    </inertial>
    <visual>
      <origin
        xyz="0 0 0"
        rpy="0 0 0" />
      <geometry>
        <mesh
          filename="package://urdfAssm2/meshes/base_link.STL" />
      </geometry>
      <material
        name="">
        <color
          rgba="0.792156862745098 0.819607843137255 0.933333333333333 1" />
      </material>
    </visual>
    <collision>
      <origin
        xyz="0 0 0"
        rpy="0 0 0" />
      <geometry>
        <mesh
          filename="package://urdfAssm2/meshes/base_link.STL" />
      </geometry>
    </collision>
  </link>
  <link
    name="swer1">
    <inertial>
      <origin
        xyz="0.00112932650883885 -0.0163068625808451 -0.00309777579378279"
        rpy="0 0 0" />
      <mass
        value="0.781511757095579" />
      <inertia
        ixx="0.000843060389202077"
        ixy="1.39670594351371E-05"
        ixz="-7.58494977239166E-06"
        iyy="0.000817015924616437"
        iyz="-3.73146040650031E-05"
        izz="0.000859803598059485" />
    </inertial>
    <visual>
      <origin
        xyz="0 0 0"
        rpy="0 0 0" />
      <geometry>
        <mesh
          filename="package://urdfAssm2/meshes/swer1.STL" />
      </geometry>
      <material
        name="">
        <color
          rgba="0.792156862745098 0.819607843137255 0.933333333333333 1" />
      </material>
    </visual>
    <collision>
      <origin
        xyz="0 0 0"
        rpy="0 0 0" />
      <geometry>
        <mesh
          filename="package://urdfAssm2/meshes/swer1.STL" />
      </geometry>
    </collision>
  </link>
  <joint
    name="rejo1"
    type="continuous">
    <origin
      xyz="0.26 -0.26 0"
      rpy="-1.5707963267949 0 -1.93881529154163" />
    <parent
      link="base_link" />
    <child
      link="swer1" />
    <axis
      xyz="0 1 0" />
  </joint>
  <link
    name="swer2">
    <inertial>
      <origin
        xyz="0.00112932650883885 -0.0163068625808454 -0.00309777579378301"
        rpy="0 0 0" />
      <mass
        value="0.78151175709558" />
      <inertia
        ixx="0.000843060389202078"
        ixy="1.39670594351372E-05"
        ixz="-7.58494977239191E-06"
        iyy="0.000817015924616439"
        iyz="-3.73146040650027E-05"
        izz="0.000859803598059486" />
    </inertial>
    <visual>
      <origin
        xyz="0 0 0"
        rpy="0 0 0" />
      <geometry>
        <mesh
          filename="package://urdfAssm2/meshes/swer2.STL" />
      </geometry>
      <material
        name="">
        <color
          rgba="0.792156862745098 0.819607843137255 0.933333333333333 1" />
      </material>
    </visual>
    <collision>
      <origin
        xyz="0 0 0"
        rpy="0 0 0" />
      <geometry>
        <mesh
          filename="package://urdfAssm2/meshes/swer2.STL" />
      </geometry>
    </collision>
  </link>
  <joint
    name="rejo2"
    type="continuous">
    <origin
      xyz="-0.26 -0.26 0"
      rpy="-1.5707963267949 0 1.20389866029615" />
    <parent
      link="base_link" />
    <child
      link="swer2" />
    <axis
      xyz="0 1 0" />
  </joint>
  <link
    name="swer3">
    <inertial>
      <origin
        xyz="0.00112932650883912 -0.0163068625808453 -0.00309777579378304"
        rpy="0 0 0" />
      <mass
        value="0.78151175709558" />
      <inertia
        ixx="0.000843060389202078"
        ixy="1.39670594351371E-05"
        ixz="-7.58494977239294E-06"
        iyy="0.000817015924616437"
        iyz="-3.73146040650033E-05"
        izz="0.000859803598059485" />
    </inertial>
    <visual>
      <origin
        xyz="0 0 0"
        rpy="0 0 0" />
      <geometry>
        <mesh
          filename="package://urdfAssm2/meshes/swer3.STL" />
      </geometry>
      <material
        name="">
        <color
          rgba="0.792156862745098 0.819607843137255 0.933333333333333 1" />
      </material>
    </visual>
    <collision>
      <origin
        xyz="0 0 0"
        rpy="0 0 0" />
      <geometry>
        <mesh
          filename="package://urdfAssm2/meshes/swer3.STL" />
      </geometry>
    </collision>
  </link>
  <joint
    name="rejo3"
    type="continuous">
    <origin
      xyz="0.26 0.26 0"
      rpy="-1.5707963267949 0 -1.93226228110303" />
    <parent
      link="base_link" />
    <child
      link="swer3" />
    <axis
      xyz="0 1 0" />
  </joint>
  <link
    name="swer4">
    <inertial>
      <origin
        xyz="0.00112932650883907 -0.0163068625808454 -0.00309777579378329"
        rpy="0 0 0" />
      <mass
        value="0.78151175709558" />
      <inertia
        ixx="0.000843060389202079"
        ixy="1.3967059435137E-05"
        ixz="-7.58494977239397E-06"
        iyy="0.000817015924616437"
        iyz="-3.73146040650027E-05"
        izz="0.000859803598059483" />
    </inertial>
    <visual>
      <origin
        xyz="0 0 0"
        rpy="0 0 0" />
      <geometry>
        <mesh
          filename="package://urdfAssm2/meshes/swer4.STL" />
      </geometry>
      <material
        name="">
        <color
          rgba="0.792156862745098 0.819607843137255 0.933333333333333 1" />
      </material>
    </visual>
    <collision>
      <origin
        xyz="0 0 0"
        rpy="0 0 0" />
      <geometry>
        <mesh
          filename="package://urdfAssm2/meshes/swer4.STL" />
      </geometry>
    </collision>
  </link>
  <joint
    name="rejo4"
    type="continuous">
    <origin
      xyz="-0.26 0.26 0"
      rpy="-1.5707963267949 0 1.21649767020403" />
    <parent
      link="base_link" />
    <child
      link="swer4" />
    <axis
      xyz="0 1 0" />
  </joint>
#####
 <joint name="S1_wheel_joint" type="continuous">     
        <origin xyz="0 0 0" rpy="1.5707 0 0"/>      
        <parent link="swer1"/>          
        <child link="S1_wheel_link"/>    
        <axis xyz="0 1 0"/>     
    </joint>

    <link name="S1_wheel_link">
        <visual>
            <origin xyz="0 0 0" rpy="1.5707 0 0" />
            <geometry>
                <cylinder radius="0.035" length = "0.05"/>
            </geometry>
            <material name="white">
                <color rgba="1 1 1 0.9"/>    
            </material>
        </visual>
    </link>
<joint name="S2_wheel_joint" type="continuous">     
        <origin xyz="0 0 0" rpy="1.5707 0 0"/>      
        <parent link="swer2"/>          
        <child link="S2_wheel_link"/>    
        <axis xyz="0 1 0"/>     
    </joint>

    <link name="S2_wheel_link">
        <visual>
            <origin xyz="0 0 0" rpy="1.5707 0 0" />
            <geometry>
                <cylinder radius="0.035" length = "0.05"/>
            </geometry>
            <material name="white">
                <color rgba="1 1 1 0.9"/>    
            </material>
        </visual>
    </link>
<joint name="S3_wheel_joint" type="continuous">     
        <origin xyz="0 0 0" rpy="1.5707 0 0"/>      
        <parent link="swer3"/>          
        <child link="S3_wheel_link"/>    
        <axis xyz="0 1 0"/>     
    </joint>

    <link name="S3_wheel_link">
        <visual>
            <origin xyz="0 0 0" rpy="1.5707 0 0" />
            <geometry>
                <cylinder radius="0.035" length = "0.05"/>
            </geometry>
            <material name="white">
                <color rgba="1 1 1 0.9"/>    
            </material>
        </visual>
    </link>
<joint name="S4_wheel_joint" type="continuous">     
        <origin xyz="0 0 0" rpy="1.5707 0 0"/>      
        <parent link="swer4"/>          
        <child link="S4_wheel_link"/>    
        <axis xyz="0 1 0"/>     
    </joint>

    <link name="S4_wheel_link">
        <visual>
            <origin xyz="0 0 0" rpy="1.5707 0 0" />
            <geometry>
                <cylinder radius="0.035" length = "0.05"/>
            </geometry>
            <material name="white">
                <color rgba="1 1 1 0.9"/>    
            </material>
        </visual>
    </link>
</robot>
